Workbook
Name RealceValor: IFERROR(IF('NOME + Nº'!#REF!="Sim", TRUE, FALSE),FALSE)

Sheet Programação Individual
C2: Descrição do bloco: | J2: Victor Barros Pedreira Ferreira (VMordekai) | P2: Atualizada em: | R2: ='NOME + Nº'!D5 -> 45182
B3: BETA | C3: ATENÇÃO: VERSÃO BETA = PRECIFICAÇÃO POR PROCESSOS! Se você estiver usando essas planilhas, entre em contato para dicas, sugestões ou atualizações. Versão nas descrições. | J3: e-mail: vmordekai@hotmail.com. Tel & Whatssap: (41) 99758-4893 | P3: VERSÃO | R3: ='NOME + Nº'!D4 -> 2023.17.3 000
C6: Leitura dos dados | AB6: Supondo Dados de Operação Ao Mês do Revendedor | AH6: Dias úteis
C7: valores fixos (escritos pelo usuário) | G7: A B C | J7: ='NOME + Nº'!C8 -> REF. NOME + Nº - 15H x 10B x 5L (cm) | U7: DADOS GERAIS DA REFERÊNCIA | AH7: 24
C8: valores calculados ou dependentes de outra célula | G8: A B C | J8: T1 | K8: CONDIÇÃO | L8: EXEMPLO "ARRANJO POR PROCESSOS"
K9: Preço de Venda | N9: =N32/N22 -> 326.73998
C10: Notas e observações | G10: A B C | K10: Metas | P10: Arranjo da Produção | V10: Custo de produção/ Unidade | Y10: ='NOME + Nº'!H123+'NOME + Nº'!K176 -> 121.51078 | AD10: Despesas Físicas
C11: Neutras | G11: A B C | K11: Orçamentos da Produção /Unidade
C12: Alternativas (CLIQUE NO BOTÃO). Ex. "SIM" ou "NÃO" | G12: NÃO | K12: Margem de Contribuição (MC) | N12: =SUM(G39:G41) -> 0.3 | P12: CELULAR | V12: Operação | X12: RELÓGIO | AE12: Aluguel | AH12: 2000
C13: Correto | G13: A B C | K13: Custo de produção/ Unidade | N13: =IF(P12=G31,0,Y10) -> 121.51078 | V13: PROCESSOS | X13: h | Y13: min | Z13: seg | AE13: Eletricidade | AH13: 500
C14: Incorreto | G14: A B C | K14: Tempo de Produção (em horas) /Unidade | O14: RELÓGIO | V14: ¹Principal | X14: ='Arranjo PROCESSOS'!BC12 -> 0 | Y14: ='Arranjo PROCESSOS'!BD12 -> 41 | Z14: ='Arranjo PROCESSOS'!BE12 -> 50 | AE14: Telefonia | AH14: 180
C15: Controles de cálculos, números livres, encerramento de tabela ou parte | G15: A B C | N15: Segundos | O15: h | P15: min | Q15: seg | V15: ²Secundária | X15: ='Arranjo PROCESSOS'!BC13 -> 0.69722222 | Y15: ='Arranjo PROCESSOS'!BD13 -> 0 | Z15: ='Arranjo PROCESSOS'!BE13 -> 0 | AE15: Seguro | AH15: 200
K16: ¹Operação Principal | M16: Costura | N16: =O16*((60^2))+(P16*60)+Q16 -> 1800 | O16: =IF(P12=G31,X24,IF(P12=G29,X14,X19)) -> 0 | P16: =IF(P12=G31,Y24,IF(P12=G29,Y14,Y19)) -> 30 | Q16: =IF(P12=G31,Z24,IF(P12=G29,Z14,Z19)) -> 0 | V16: ³Pausa programadas (funcionário/dia) | Y16: 45 | Z16: 0 | AE16: Outros | AH16: 80
C17: Destaques livres ou estéticos | G17: Cores diversas | K17: ²Operação Secundária | M17: Auxiliar | N17: =(O17*(60^2))+(P17*60)+Q17 -> 600 | O17: =IF(P12=G31,X25,IF(P12=G29,X15,X20)) -> 0 | P17: =IF(P12=G31,Y25,IF(P12=G29,Y15,Y20)) -> 10 | Q17: =IF(P12=G31,Z25,IF(P12=G29,Z15,Z20)) -> 0 | AF17: Subtotal | AH17: =SUM(AH12:AH16) -> 2960
K18: ³Tempo improdutivo (funcionário/dia) | N18: =(O18*(60^2))+(P18*60)+Q18 -> 2700 | O18: =IF(P12=G31,X26,IF(P12=G29,X16,X21)) -> 0 | P18: =IF(P12=G31,Y26,IF(P12=G29,Y16,Y21)) -> 45 | Q18: =IF(P12=G31,Z26,IF(P12=G29,Z16,Z21)) -> 0 | V18: CELULAR | X18: h | Y18: min | Z18: seg | AD18: Funcionários
K19: 1800 | V19: =V14 -> ¹Principal | X19: ='Arranjo CELULAR'!P54 -> 0 | Y19: ='Arranjo CELULAR'!Q54 -> 30 | Z19: ='Arranjo CELULAR'!R54 -> 0
K20: Estatísticas da Produção | V20: =V15 -> ²Secundária | X20: ='Arranjo CELULAR'!P56 -> 0 | Y20: ='Arranjo CELULAR'!Q56 -> 10 | Z20: ='Arranjo CELULAR'!R56 -> 0 | AE20: Quantidade | AH20: 4
B21: VMORDEKAI | K21: Capacidade Efetiva desse produto (%) | N21: 0.7 | V21: =V16 -> ³Pausa programadas (funcionário/dia) | Y21: 45 | Z21: 0 | AE21: Média salarial mensal bruta | AH21: 2300
K22: Quantidade produzida por mês | N22: =N23*N26*N21 -> 520.674 | AE22: Outros | AH22: 600
K23: Produção/dia | N23: =(N38)*N39*N21/N16 -> 33.81 | P23: PRODUÇÃO DE LOTE | V23: UTILIZAÇÃO | X23: h | Y23: min | Z23: seg | AF23: Subtotal | AH23: =(AH21*AH20)+AH22 -> 9800
D24: Mês de referência: | F24: (mês) | K24: Carrinhos de abastecimento/dia | N24: =(N38)*N21/K19 -> 11.27 | P24: TEMPO PARA FAZER | R24: 75 | T24: Unidades | V24: =V19 -> ¹Principal | X24: 1 | Y24: 0 | Z24: 0 | AD24: Outras Despesas ou Investimentos
D25: Última atualização | F25: (data) | K25: Total de produtos recolhidos por Carrinhos | N25: =N23/N24 -> 3 | P25: TOTAL | R25: =R24/N23 -> 2.2182786 | T25: DIAS | V25: =V20 -> ²Secundária | X25: 0 | Y25: 20 | Z25: ='Arranjo CELULAR'!R61 -> 0
K26: Dias úteis de Produção | N26: =G36 -> 22 | V26: =V21 -> ³Pausa programadas (funcionário/dia) | Y26: 45 | Z26: 0 | AE26: publicidade e propaganda | AH26: 200
B27: PRECIFICAÇÃO POR PROCESSOS? | G27: NÃO | K27: Custos (Insumos, Matéria-Prima) | N27: =N13*N22 -> 63267.502 | AE27: Empréstimos e Taxas | AH27: 1000
K28: *Despesas Físicas | N28: =SUM(G309:G314) -> 11760 | AE28: Outros | AH28: 0
C29: Arranjo da Produção | G29: PROCESSOS | K29: Despesas com Funcionários | N29: =F68 -> 53337.891 | AF29: Subtotal | AH29: =SUM(AH26:AH28) -> 1200
G30: CELULAR | K30: Outras Despesas | N30: =SUM(G318:G320) -> 2500
G31: UTILIZAÇÃO | K31: Despesa Total | N31: =SUM(N27:N30) -> 130865.39 | AG31: TOTAL | AH31: =AH17+AH29+AH23 -> 13960
K32: Montante | N32: =N31+(N31*N12) -> 170125.01
C33: =B3 -> BETA | D33: Dados gerais da empresa | K33: Receita Mensal | N33: =N32-N31 -> 39259.618
AC34: Preço de venda direto e sugestão de revenda | AH34: Parâmetros do Revendedor
K35: Funcionarios | AC35: =J7 -> REF. NOME + Nº - 15H x 10B x 5L (cm)
D36: Dias úteis/mês em operação | G36: 22 | K36: Operador Principal | AB36: =J8 -> T1 | AC36: =L8 -> EXEMPLO "ARRANJO POR PROCESSOS" | AH36: Ao Mês | AJ36: Vendas por dia
C37: OPERAÇÃO | D37: Utilização da Capacidade (%) | G37: 0.7 | M37: h | N37: s | AF37: Preços | AG37: fator (%) | AH37: Valor (R$) | AI37: Quant.
D38: └Tolerância da Capacidade (%) | G38: 0.1 | K38: Carga horária por funcionário/dia | M38: =G72 -> 8.8 | N38: =(M38*60*60)-N18 -> 28980 | AC38: Preço sugerido para revenda | AF38: =AF40*AG38/AG40 -> 594.07268 | AG38: 100 | AH38: =AG38*AH43/AG43 -> 93066.667 | AI38: =AH38/AF38 -> 156.65872 | AJ38: =AI38/AH7 -> 6.5274467
D39: Impostos Totais | G39: 0.05 | K39: Quantidade de Costureiras (os) | N39: =G73 -> 3 | AB39: fatores | AC39: (-) Impostos s/Vendas | AF39: =(AF40*AG39)/AG40 -> 59.407268 | AG39: 10 | AH39: =AH43*AG39/AG43 -> 9306.6667
D40: MCAE* | G40: 0.1 | AC40: (-) Custo das Mercadorias Vendidas | AF40: =N9 -> 326.73998 | AG40: 55 | AH40: =AH43*AG40/AG43 -> 51186.667
D41: Lucro Desejado (%) | G41: 0.15 | K41: ¹ Operação deve estar com margem de tolerância | AC41: (-) Despesas Variáveis | AF41: =(AF40*AG41)/AG40 -> 59.407268 | AG41: 10 | AH41: =AH43*AG41/AG43 -> 9306.6667
D42: *MCAE - Margem de Contribuição para Ações Estratégicas | K42: ² Não determina a Produção OU a Operação que pode ser terceirizada | AC42: (=) Margem de Contribuição (Final) | AF42: =(AF40*AG42)/AG40 -> 148.51817 | AG42: =AG38-(SUM(AG39:AG41)) -> 25 | AH42: =AG42*AH43/AG43 -> 23266.667
D43: MARK-UP | K43: ³ Paradas programadas e não programadas, exemplo: 30 min e 15 min, respectivamente | AC43: (-) Despesas Fixas | AF43: =(AF40*AG43)/45 -> 108.91333 | AG43: 15 | AH43: =AH31 -> 13960
...

Sheet NOME + Nº
B2: ='Programação Individual'!B21 -> VMORDEKAI
B4: Versão da Planilha | D4: 2023.17.3 000 | I4: Modelista | J4: Victor Ferreira | L4: 45182
B5: By Victor Ferreira | D5: 45182 | I5: Dados: | J5: Victor Ferreira | L5: 45182
B7: NOME | C7: NOME + Nº
B8: REFERÊNCIA | C8: =IF(C7=0,"Informe o nome da referência!",CONCATENATE(LEFT(B8,3),". ",C7," - ",D13,"H x ",D14,"B x ",D15,"L (cm)")) -> REF. NOME + Nº - 15H x 10B x 5L (cm)
B10: 1 | C10: DESCRIÇÃO GERAL
B12: DIMENSÕES (cm) | F12: OBSERVAÇÕES ADICIONAIS | J12: LEGENDA DE PRAZOS
B13: Altura (H - Altura máxima) | D13: 15 | F13: DESCRIÇÃO | H13: VALOR | J13: Validade do Orçamento
B14: Base (B - Vista Frontal) | D14: 10 | J14: STATUS | K14: DIAS | L14: (HOJE - PRAZO)
B15: Largura (L - Vista Lateral) | D15: 5 | J15: Prazo Máximo | K15: 90 | L15: =TODAY()-K15 -> 45650
B16: (Outro parâmetro) | J16: Fase Inicial | K16: 7 | L16: =TODAY()-K16 -> 45733
B17: (Outro parâmetro) | J17: Desenvolvimento | K17: 30 | L17: =TODAY()-K17 -> 45710
B18: Margem | D18: 1 | J18: Limite | K18: 60 | L18: =TODAY()-K18 -> 45680
B19: Alça | D19: SIM | E19: =IF(D19="SIM","1","0") -> 1 | J19: Dead Line | K19: 90 | L19: =TODAY()-K19 -> 45650
B20: Alça Dupla | D20: NÃO | E20: =IF(D20="SIM","2","1") -> 1
B21: Alça Largura | D21: 3
B22: Vivo | D22: NÃO | E22: =IF(D22="SIM","1","0") -> 0
B23: Entretela | D23: NÃO | E23: =IF(D23="SIM","1","0") -> 0
B24: Forro | D24: NÃO | E24: =IF(D24="SIM","1","0") -> 0
B25: Couro | D25: NÃO | E25: =IF(D25="SIM","1","0") -> 0
B26: Tec. Vivo | D26: NÃO | E26: =IF(D26="SIM","1","0") -> 0
B27: Estrutura | D27: NÃO | E27: =IF(D27="SIM","1","0") -> 0
B28: Reforço | D28: NÃO | E28: =IF(D28="SIM","1","0") -> 0
B30: =B10+1 -> 2 | C30: TECIDOS
B31: PLANILHAS REVISADAS?
B32: MODELAGEM | C32: SIM | F32: TIPO DE ORÇAMENTO POR: | H32: =IF(E42=0,D47,IF(E42=(1+IF(D23="SIM","1","0")+IF(D24="SIM","1","0")+IF(D25="SIM","1","0")+IF(D26="SIM","1","0")+IF(D27="SIM","1","0")),D48,D49)) -> MOLDES | I32: =IF(H32=D47,E47, IF(H32=D48,E48, IF(H32=D49,E49,"0"))) -> INDIVIDUAL
B33: ENFESTO | C33: NÃO
D34: Descrição | E34: TIPO | F34: FORNECEDOR | G34: QUANTIDADE* | H34: Valor (R$) | I34: Data FORNECENOR | J34: Largura (cm) | K34: Consumo | L34: Observações
B35: Tec. Externo | D35: Aquablock | E35: MOLDES | F35: BRASILUSA | G35: =ENFESTO!AU274/H128 -> 0 | H35: 49.9 | I35: 45133 | J35: 140 | K35: =IF(E35=D47,MODELAGEM!EG14,IF(H50=1,H35*G35,"ERRO")) -> 8.9467765
B36: =B23 -> Entretela | D36: 80 | E36: MOLDES | F36: VOLUNTÁRIOS | G36: =ENFESTO!AU275/H128 -> 0 | H36: 16 | I36: 45133 | J36: 75 | K36: =IF(J36>0,IF(E36=D47, (MODELAGEM!EG15)*E23,IF(H50=1,H36*G36*E23,"ERRO")),0) -> 0
B37: =B24 -> Forro | D37: Suede | E37: MOLDES | F37: BRASILUSA | G37: =ENFESTO!AU276/H128 -> 0 | H37: 19.9 | I37: 45133 | J37: 140 | K37: =IF(J37>0,IF(E37=D47, (MODELAGEM!EG16)*E24, IF(H50=1,H37*G37*E24,"ERRO")),0) -> 0
B38: =B25 -> Couro | D38: Couro Legítimo Fly | E38: MOLDES | F38: ROMA PLÁSTICOS | G38: =ENFESTO!AU277/H128 -> 0 | H38: 74.9 | I38: 45133 | J38: 100 | K38: =IF(J38>0,IF(E38=D47, (MODELAGEM!EG17)*E25, IF(H50=1, H38*G38*E25,"ERRO")),0) -> 0
B39: =B26 -> Tec. Vivo | D39: =D35 -> Aquablock | E39: MOLDES | F39: =F35 -> BRASILUSA | G39: =ENFESTO!AU278/H128 -> 0 | H39: =H35 -> 49.9 | I39: =I35 -> 45133 | J39: =J35 -> 140 | K39: =IF(J39>0,IF(E39=D47, (MODELAGEM!EG18)*E26, IF(H50=1, H39*G39*E26,"ERRO")),0) -> 0
B40: =B27 -> Estrutura | D40: Placa Plástica | E40: MOLDES | F40: ROMA PLÁSTICOS | G40: =ENFESTO!AU279/H128 -> 0 | H40: 20.12 | I40: 45182 | J40: 28 | K40: =IF(J40>0,IF(E40=D47, (MODELAGEM!EG19)*E27, IF(H50=1,H40*G40*E27,"ERRO")),0) -> 0
B41: =B28 -> Reforço | D41: TNT 120 | E41: MOLDES | F41: ROMA PLÁSTICOS | G41: =ENFESTO!AU281/H129 -> 0 | H41: 7.9 | I41: 45133 | J41: 140 | K41: =IF(J41>0,IF(E41=D47, (MODELAGEM!EG20)*E28, IF(H50=1,H41*G41*E28,"ERRO")),0) -> 0
E42: =IF(E35=D47,"0","1")+IF(D23="SIM",IF(E36=D47,"0","1"),"0")+IF(D24="SIM",IF(E37=D47,"0","1"),"0")+IF(D25="SIM",IF(E38=D47,"0","1"),"0")+IF(D26="SIM",IF(E39=D47,"0","1"),"0")+IF(D27="SIM",IF(E40=D47,"0","1"),"0") -> 0 | F42: *QUANTIDADE: peças fechadas ou metro por ENFESTO | I42: =IF(SUM(I35:I40)>0,SMALL(I35:I40,1),TODAY()) -> 45133 | J42: Consumo | K42: =K35+IF(D23="SIM",K36,0)+IF(D24="SIM",K37,0)+IF(D25="SIM",K38,0)+IF(D26="SIM",K39,0)+IF(D27="SIM",K40,0)+IF(D28="SIM",K41,0) -> 8.9467765
D44: Descrição
D45: TIPO DE ORÇAMENTO DE TECIDOS POR:
D46: Tipos | E46: Recomendação | G46: Características
D47: MOLDES | E47: INDIVIDUAL | G47: Máximo de aproveitamento | J47: Considera moldes CORTADOS individualmente
...

Sheet CÓPIA (exportar imagem)
D5: CÓPIA PARA EXPORTAÇÃO - PREÇO: Planilha de Precificação
D6: ='Programação Individual'!B21 -> VMORDEKAI
E7: ='NOME + Nº'!C181 -> PREÇO FINAL
J8: DATA: | K8: ='NOME + Nº'!L5 -> 45182 | P8: LEGENDA
E9: ='NOME + Nº'!D184 -> REFERÊNCIA | F9: ='NOME + Nº'!E184 -> REF. NOME + Nº - 15H x 10B x 5L (cm) | P9: Validade do Orçamento
P10: STATUS | R10: DIAS | T10: (HOJE - PRAZO)
F11: ='NOME + Nº'!E186 -> DESCONTO (%) | I11: ='NOME + Nº'!H186 -> 0 | P11: Prazo Máximo | R11: ='NOME + Nº'!K15 -> 90 | T11: =TODAY()-R11 -> 45650
P12: Fase Inicial | R12: ='NOME + Nº'!K16 -> 7 | T12: =TODAY()-R12 -> 45733
E13: ='NOME + Nº'!D188 -> QUANTIDADE | F13: ='NOME + Nº'!E188 -> 20 | H13: ='NOME + Nº'!G188 -> BASE | I13: ='NOME + Nº'!H188 -> FINAL | J13: ='NOME + Nº'!I188 -> OFERTA | P13: Desenvolvimento | R13: ='NOME + Nº'!K17 -> 30 | T13: =TODAY()-R13 -> 45710
E14: ='NOME + Nº'!D189 -> LOTE | F14: ='NOME + Nº'!E189 -> Valor Base + Acréscimos finais | H14: ='NOME + Nº'!G189 -> 8505.7544 | I14: ='NOME + Nº'!H189 -> 8505.7544 | J14: ='NOME + Nº'!I189 -> 8505.7544 | P14: Limite | R14: ='NOME + Nº'!K18 -> 60 | T14: =TODAY()-R14 -> 45680
P15: Dead Line | R15: ='NOME + Nº'!K19 -> 90 | T15: =TODAY()-R15 -> 45650
E16: ='NOME + Nº'!D191 -> UNITÁTIO | F16: ='NOME + Nº'!E191 -> Valor Base + Acréscimos finais | H16: ='NOME + Nº'!G191 -> 425.28772 | I16: ='NOME + Nº'!H191 -> 425.28772 | J16: ='NOME + Nº'!I191 -> 425.28772
E18: Data | F18: Nota | J18: Valor (R$)
E19: =IF('NOME + Nº'!D194=0,"",'NOME + Nº'!D194) | F19: =IF('NOME + Nº'!E194=0,"",'NOME + Nº'!E194) | J19: =IF('NOME + Nº'!I194=0,"",'NOME + Nº'!I194)
E20: =IF('NOME + Nº'!D195=0,"",'NOME + Nº'!D195) | F20: =IF('NOME + Nº'!E195=0,"",'NOME + Nº'!E195) | J20: =IF('NOME + Nº'!I195=0,"",'NOME + Nº'!I195)
E21: =IF('NOME + Nº'!D196=0,"",'NOME + Nº'!D196) | F21: =IF('NOME + Nº'!E196=0,"",'NOME + Nº'!E196) | J21: =IF('NOME + Nº'!I196=0,"",'NOME + Nº'!I196)
E22: =IF('NOME + Nº'!D197=0,"",'NOME + Nº'!D197) | F22: =IF('NOME + Nº'!E197=0,"",'NOME + Nº'!E197) | J22: =IF('NOME + Nº'!I197=0,"",'NOME + Nº'!I197)
E23: =IF('NOME + Nº'!D198=0,"",'NOME + Nº'!D198) | F23: =IF('NOME + Nº'!E198=0,"",'NOME + Nº'!E198) | J23: =IF('NOME + Nº'!I198=0,"",'NOME + Nº'!I198)
H24: =IF('NOME + Nº'!G199=0,"",'NOME + Nº'!G199)
D26: CÓPIA PARA EXPORTAÇÃO - CONSUMO DE MATERIAIS: Planilha de ENFESTO
D27: ='Programação Individual'!B21 -> VMORDEKAI
E28: =ENFESTO!W10 -> REF. NOME + Nº - 15H x 10B x 5L (cm)
E29: CONSUMO DE TECIDO POR MOLDE
E30: =IF('NOME + Nº'!$C$32="NÃO","!!MODELAGEM não atualizada!!","") | I30: =J8 -> DATA: | J30: =K8 -> 45182
F31: ENCOMENDA
E32: LOTE | F32: =ENFESTO!K18 -> 20
E33: LISTA DE TECIDOS | I33: Soma Total
E34: TECIDO | F34: Descrição | G34: VALOR (R$/m) | H34: Largura | I34: Metros | J34: R$
D35: 1 | E35: =ENFESTO!J21 -> Tec. Externo | F35: =ENFESTO!K21 -> Aquablock | G35: =ENFESTO!L21 -> 49.9 | H35: =ENFESTO!M21 -> 140 | I35: =ENFESTO!N21 -> 4.1447059 | J35: =ENFESTO!O21 -> 206.82082 | AR35: =ENFESTO!Y289 -> FICHA DE ENFESTO & CORTE
D36: 2 | E36: =ENFESTO!J22 | F36: =ENFESTO!K22 | G36: =ENFESTO!L22 | H36: =ENFESTO!M22 | I36: =ENFESTO!N22 -> 0 | J36: =ENFESTO!O22 -> 0
D37: 3 | E37: =ENFESTO!J23 | F37: =ENFESTO!K23 | G37: =ENFESTO!L23 | H37: =ENFESTO!M23 | I37: =ENFESTO!N23 -> 0 | J37: =ENFESTO!O23 -> 0 | AR37: =IF('NOME + Nº'!$C$33="NÃO","!!ENFESTO não atualizado!!",IF(ENFESTO!Y291=0,"",ENFESTO!Y291)) -> !!ENFESTO não atualizado!!
D38: 4 | E38: =ENFESTO!J24 | F38: =ENFESTO!K24 | G38: =ENFESTO!L24 | H38: =ENFESTO!M24 | I38: =ENFESTO!N24 -> 0 | J38: =ENFESTO!O24 -> 0
D39: 5 | E39: =ENFESTO!J25 | F39: =ENFESTO!K25 | G39: =ENFESTO!L25 | H39: =ENFESTO!M25 | I39: =ENFESTO!N25 -> 0 | J39: =ENFESTO!O25 -> 0 | AR39: MATERIAL | AT39: DESCRIÇÃO | AZ39: Valor | BA39: Obs.
D40: 6 | E40: =ENFESTO!J26 | F40: =ENFESTO!K26 | G40: =ENFESTO!L26 | H40: =ENFESTO!M26 | I40: =ENFESTO!N26 -> 0 | J40: =ENFESTO!O26 -> 0 | AQ40: 1 | AR40: =IF(ENFESTO!Y294=0,"",ENFESTO!Y294) -> Tec. Principal | AT40: =IF(ENFESTO!AA294=0,"",ENFESTO!AA294) -> EX.: No ENFESTO 1 foi posicionado moldes 1,2,6, alinhando posições de fio e maximizando aproveitamento. | AZ40: =IF(ENFESTO!AG294=0,"",ENFESTO!AG294) -> 60cm | BA40: =IF(ENFESTO!AH294=0,"",ENFESTO!AH294)
D41: 7 | E41: =ENFESTO!J27 | F41: =ENFESTO!K27 | G41: =ENFESTO!L27 | H41: =ENFESTO!M27 | I41: =ENFESTO!N27 -> 0 | J41: =ENFESTO!O27 -> 0
F43: CONSUMO TOTAL | I43: =ENFESTO!N29 -> 4.1447059 | J43: =ENFESTO!O29 -> 206.82082
AQ44: 2 | AR44: Tec. Principal
D46: ='Programação Individual'!B21 -> VMORDEKAI
E47: =ENFESTO!W10 -> REF. NOME + Nº - 15H x 10B x 5L (cm) | AQ47: 3 | AR47: Tec. Principal
E48: =ENFESTO!J34 -> CONSUMO DE TECIDO POR ENFESTO
...

Sheet MODELAGEM
B2: Leitura dos dados
B3: valores fixos (escritos pelo usuário) | F3: A B C
B4: valores calculados ou dependentes de outra célula | F4: A B C | J4: ='NOME + Nº'!C8 -> REF. NOME + Nº - 15H x 10B x 5L (cm)
J5: CONSUMO DE TECIDO POR MOLDE
B6: Notas e observações | F6: A B C | J6: ENCOMENDA | K6: MÍNIMO IDEAL
B7: Neutras | F7: A B C
B8: Alternativas (CLIQUE NO BOTÃO). Ex. "SIM" ou "NÃO" | F8: SIM | I8: LOTE | J8: ='NOME + Nº'!H128 -> 20 | K8: =INT(MAX((T11:T73),(W259,W266,W273,W280))) -> 35 | M8: TECIDO | P8: MOLDE | R8: ENFESTO
B9: Correto | F9: A B C | M9: Tipo | N9: VALOR (R$/m) | O9: TECIDO TOTAL | P9: Comprimento | Q9: Largura | R9: Máximo | S9: Subtotal | T9: LOTE MÍNIMO | U9: Quantidade de Moldes | X9: CÁLCULO DE CONSUMO
B10: Incorreto | F10: A B C | J10: CORTES | L10: Quantidade
B11: Controles de cálculos, números livres, encerramento de tabela ou parte | F11: A B C | G11: 1 | H11: =CONCATENATE("MOLDE ",G11) -> MOLDE 1 | J11: 1 | K11: SIM | L11: 1 | M11: Tec. Externo | N11: =IF((M11=X14),Z14,(IF((M11=X15),Z15,(IF((M11=X16),Z16,(IF((M11=X17),Z17,(IF((M11=X18),Z18,(IF((M11=X19),Z19,(IF((M11=X20),Z20))))))))))))) -> 49.9 | O11: =IF((M11=X14),AA14,(IF((M11=X15),AA15,(IF((M11=X16),AA16,(IF((M11=X17),AA17,(IF((M11=X18),AA18,(IF((M11=X19),AA19,(IF((M11=X20),AA20))))))))))))) -> 140 | P11: 34.4 | Q11: 58.3 | R11: =IF(R12<(M12*L11), INT(R12),(M12*L11)) -> 2 | S11: =IF(K11="SIM",(N11*L11*(P11/100)/R11)*L12,0) -> 8.5828 | T11: =R12*L12 -> 2.4013722 | U11: =IF(K11="SIM",1,IF(K13="SIM",1,IF(K15="SIM",1,IF(K17="SIM",1,0)))) -> 1 | AB11: Moldes Consumo
H12: CORPO | L12: =IF(K11="SIM","1","0") -> 1 | M12: =J8 -> 20 | R12: =O11/(Q11) -> 2.4013722 | X12: LISTA DE TECIDOS | AB12: =H11 -> MOLDE 1 | AF12: =H20 -> MOLDE 2 | AJ12: =H29 -> MOLDE 3 | AN12: =H38 -> MOLDE 4 | AR12: =H47 -> MOLDE 5 | AV12: =H56 -> MOLDE 6 | AZ12: =H65 -> MOLDE 7 | BD12: =H74 -> MOLDE 8 | BH12: =H83 -> MOLDE 9 | BL12: =H92 -> MOLDE 10 | BP12: =H101 -> MOLDE 11 | BT12: =H110 -> MOLDE 12 | BX12: =H119 -> MOLDE 13 | CB12: =H128 -> MOLDE 14 | CF12: =H137 -> MOLDE 15 | CJ12: =H146 -> MOLDE 16 | CN12: =H155 -> MOLDE 17 | CR12: =H164 -> MOLDE 18 | CV12: =H173 -> MOLDE 19 | CZ12: =H182 -> MOLDE 20 | DD12: =H191 -> MOLDE 21 | DH12: =H200 -> MOLDE 22 | DL12: =H209 -> MOLDE 23 | DP12: =H218 -> MOLDE 24 | DT12: =H227 -> MOLDE 25 | DX12: =H236 -> MOLDE 26 | EB12: Moldes ALÇAS | EF12: VIVO | EG12: Soma Total | EI12: ALÇAS Soma Total
B13: Destaques livres ou estéticos | F13: Cores diversas | J13: =J11+1 -> 2 | K13: SIM | L13: 1 | M13: Reforço | N13: =IF((M13=X14),Z14,(IF((M13=X15),Z15,(IF((M13=X16),Z16,(IF((M13=X17),Z17,(IF((M13=X18),Z18,(IF((M13=X19),Z19,(IF((M13=X20),Z20))))))))))))) -> 7.9 | O13: =IF((M13=X14),AA14,(IF((M13=X15),AA15,(IF((M13=X16),AA16,(IF((M13=X17),AA17,(IF((M13=X18),AA18,(IF((M13=X19),AA19,(IF((M13=X20),AA20))))))))))))) -> 140 | P13: =P11 -> 34.4 | Q13: =Q11 -> 58.3 | R13: =IF(R14<(M14*L13), INT(R14),(M14*L13)) -> 2 | S13: =IF(K13="SIM",(N13*L13*(P13/100)/R13)*L14,0) -> 1.3588 | T13: =R14*L14 -> 2.4013722 | X13: MATERIAL | Y13: Descrição | Z13: VALOR (R$/m) | AA13: Largura | AB13: 1 | AC13: =AB13+1 -> 2 | AD13: =AC13+1 -> 3 | AE13: =AD13+1 -> 4 | AF13: =AE13+1 -> 5 | AG13: =AF13+1 -> 6 | AH13: =AG13+1 -> 7 | AI13: =AH13+1 -> 8 | AJ13: =AI13+1 -> 9 | ... EF13: =EE13+1 -> 109
L14: =IF(K13="SIM","1","0") -> 1 | M14: =M12 -> 20 | R14: =O13/(Q13) -> 2.4013722 | W14: 1 | X14: ='NOME + Nº'!B35 -> Tec. Externo | Y14: ='NOME + Nº'!D35 -> Aquablock | Z14: ='NOME + Nº'!H35 -> 49.9 | AA14: ='NOME + Nº'!J35 -> 140 | AB14: =IF((M11=X14), S11, 0) -> 8.5828 | AC14: =IF((M13=X14), S13, 0) -> 0 | AD14: =IF((M15=X14), S15, 0) -> 0 | AE14: =IF((M17=X14), S17, 0) -> 0 | AF14: =IF((M20=X14), S20, 0) -> 0 | AG14: =IF((M22=X14), S22, 0) -> 0 | AH14: =IF((M24=X14), S24, 0) -> 0 | AI14: =IF((M26=X14), S26, 0) -> 0 | AJ14: =IF((M29=X14), S29, 0) -> 0 | AK14: =IF((M31=X14), S31, 0) -> 0 | AL14: =IF((M33=X14), S33, 0) -> 0 | AM14: =IF((M35=X14), S35, 0) -> 0 | AN14: =IF((M38=X14), S38, 0) -> 0 | AO14: =IF((M40=X14), S40, 0) -> 0 | AP14: =IF((M42=X14), S42, 0) -> 0 | AQ14: =IF((M44=X14), S44, 0) -> 0 | AR14: =IF((M47=X14), S47, 0) -> 0 | AS14: =IF((M49=X14), S49, 0) -> 0 | AT14: =IF((M51=X14), S51, 0) -> 0 | AU14: =IF((M53=X14), S53, 0) -> 0 | AV14: =IF((M56=X14), S56, 0) -> 0 | AW14: =IF((M58=X14), S58, 0) -> 0 | AX14: =IF((M60=X14), S60, 0) -> 0 | AY14: =IF((M62=X14), S62, 0) -> 0 | AZ14: =IF((M65=X14), S65, 0) -> 0 | BA14: =IF((M67=X14), S67, 0) -> 0 | BB14: =IF((M69=X14), S69, 0) -> 0 | BC14: =IF((M71=X14), S71, 0) -> 0 | BD14: =IF((M74=X14), S74, 0) -> 0 | BE14: =IF((M76=X14), S76, 0) -> 0 | BF14: =IF((M78=X14), S78, 0) -> 0 | BG14: =IF((M80=X14), S80, 0) -> 0 | BH14: =IF((M83=X14), S83, 0) -> 0 | BI14: =IF((M85=X14), S85, 0) -> 0 | BJ14: =IF((M87=X14), S87, 0) -> 0 | BK14: =IF((M89=X14), S89, 0) -> 0 | BL14: =IF((M92=X14), S92, 0) -> 0 | BM14: =IF((M94=X14), S94, 0) -> 0 | BN14: =IF((M96=X14), S96, 0) -> 0 | BO14: =IF((M98=X14), S98, 0) -> 0 | BP14: =IF((M101=X14), S101, 0) -> 0 | BQ14: =IF((M103=X14), S103, 0) -> 0 | BR14: =IF((M105=X14), S105, 0) -> 0 | BS14: =IF((M107=X14), S107, 0) -> 0 | BT14: =IF((M110=X14), S110, 0) -> 0 | BU14: =IF((M112=X14), S112, 0) -> 0 | BV14: =IF((M114=X14), S114, 0) -> 0 | BW14: =IF((M116=X14), S116, 0) -> 0 | BX14: =IF((M119=X14), S119, 0) -> 0 | BY14: =IF((M121=X14), S121, 0) -> 0 | BZ14: =IF((M123=X14), S123, 0) -> 0 | CA14: =IF((M125=X14), S125, 0) -> 0 | CB14: =IF((M128=X14), S128, 0) -> 0 | CC14: =IF((M130=X14), S130, 0) -> 0 | CD14: =IF((M132=X14), S132, 0) -> 0 | CE14: =IF((M134=X14), S134, 0) -> 0 | CF14: =IF((M137=X14), S137, 0) -> 0 | CG14: =IF((M139=X14), S139, 0) -> 0 | CH14: =IF((M141=X14), S141, 0) -> 0 | CI14: =IF((M143=X14),S143, 0) -> 0 | CJ14: =IF((M146=X14), S146, 0) -> 0 | CK14: =IF((M148=X14), S148, 0) -> 0 | CL14: =IF((M150=X14), S150, 0) -> 0 | CM14: =IF((M152=X14), S152, 0) -> 0 | CN14: =IF((M155=X14), S155, 0) -> 0 | CO14: =IF((M157=X14), S157, 0) -> 0 | CP14: =IF((M159=X14), S159, 0) -> 0 | CQ14: =IF((M161=X14), S161, 0) -> 0 | CR14: =IF((M164=X14), S164, 0) -> 0 | CS14: =IF((M166=X14), S166, 0) -> 0 | CT14: =IF((M168=X14), S168, 0) -> 0 | CU14: =IF((M170=X14), S170, 0) -> 0 | CV14: =IF((M173=X14), S173, 0) -> 0 | CW14: =IF((M175=X14), S175, 0) -> 0 | CX14: =IF((M177=X14), S177, 0) -> 0 | CY14: =IF((M179=X14), S179, 0) -> 0 | CZ14: =IF((M182=X14), S182, 0) -> 0 | DA14: =IF((M184=X14), S184, 0) -> 0 | DB14: =IF((M186=X14), S186, 0) -> 0 | DC14: =IF((M188=X14), S188, 0) -> 0 | DD14: =IF((M191=X14), S191, 0) -> 0 | DE14: =IF((M193=X14), S193, 0) -> 0 | DF14: =IF((M195=X14), S195, 0) -> 0 | DG14: =IF((M197=X14), S197, 0) -> 0 | DH14: =IF((M200=X14), S200, 0) -> 0 | DI14: =IF((M202=X14), S202, 0) -> 0 | DJ14: =IF((M204=X14), S204, 0) -> 0 | DK14: =IF((M206=X14), S206, 0) -> 0 | DL14: =IF((M209=X14), S209, 0) -> 0 | DM14: =IF((M211=X14), S211, 0) -> 0 | DN14: =IF((M213=X14), S213, 0) -> 0 | DO14: =IF((M215=X14), S215, 0) -> 0 | DP14: =IF((M218=X14), S218, 0) -> 0 | DQ14: =IF((M220=X14), S220, 0) -> 0 | DR14: =IF((M222=X14), S222, 0) -> 0 | DS14: =IF((M224=X14), S224, 0) -> 0 | DT14: =IF((M227=X14), S227, 0) -> 0 | DU14: =IF((M229=X14), S229, 0) -> 0 | DV14: =IF((M231=X14), S231, 0) -> 0 | DW14: =IF((M233=X14), S233, 0) -> 0 | DX14: =IF((M236=X14), S236, 0) -> 0 | DY14: =IF((M238=X14), S238, 0) -> 0 | DZ14: =IF((M240=X14), S240, 0) -> 0 | EA14: =IF((M242=X14), S242, 0) -> 0 | EB14: =IF('NOME + Nº'!E62="SIM",0,IF((M259=X14), V259+IF(H259="SIM",IF((P259=X14),SUM(V260:V263), 0)), IF(H259="SIM",IF((P259=X14),SUM(V260:V263), 0)))) -> 0.36397647 | EC14: =IF('NOME + Nº'!E62="SIM",0,IF((M266=X14), V266+IF(H259="SIM",IF((P266=X14),SUM(V267:V270), 0)), IF(H259="SIM",IF((P266=X14),SUM(V267:V270), 0)))) -> 0 | ED14: =IF('NOME + Nº'!E62="SIM",0,IF((M273=X14), V273+IF(H259="SIM",IF((P273=X14),SUM(V274:V277), 0)), IF(H259="SIM",IF((P273=X14),SUM(V274:V277), 0)))) -> 0 | EE14: =IF('NOME + Nº'!E62="SIM",0,IF((M280=X14), V280+IF(H259="SIM",IF((P280=X14),SUM(V281:V284), 0)), IF(H259="SIM",IF((P280=X14),SUM(V281:V284), 0)))) -> 0 | EF14: =IF(AE33=X14,AE49,0) -> 0 | EG14: =SUM(AB14:EF14) -> 8.9467765 | EI14: =SUM(EB14:EE14) -> 0.36397647
J15: =J13+1 -> 3 | K15: SIM | L15: 1 | M15: Reforço | N15: =IF((M15=X14),Z14,(IF((M15=X15),Z15,(IF((M15=X16),Z16,(IF((M15=X17),Z17,(IF((M15=X18),Z18,(IF((M15=X19),Z19,(IF((M15=X20),Z20))))))))))))) -> 7.9 | O15: =IF((M15=X14),AA14,(IF((M15=X15),AA15,(IF((M15=X16),AA16,(IF((M15=X17),AA17,(IF((M15=X18),AA18,(IF((M15=X19),AA19,(IF((M15=X20),AA20))))))))))))) -> 140 | P15: =P13 -> 34.4 | Q15: =Q13 -> 58.3 | R15: =IF(R16<(M16*L15), INT(R16),(M16*L15)) -> 2 | S15: =IF(K15="SIM",(N15*L15*(P15/100)/R15)*L16,0) -> 1.3588 | T15: =R16*L16 -> 2.4013722 | W15: 2 | X15: ='NOME + Nº'!B23 -> Entretela | Y15: ='NOME + Nº'!D36 -> 80 | Z15: ='NOME + Nº'!H36 -> 16 | AA15: ='NOME + Nº'!J36 -> 75 | AB15: =IF((M11=X15), S11, 0) -> 0 | AC15: =IF((M13=X15), S13, 0) -> 0 | AD15: =IF((M15=X15), S15, 0) -> 0 | AE15: =IF((M17=X15), S17, 0) -> 0 | AF15: =IF((M20=X15), S20, 0) -> 0 | AG15: =IF((M22=X15), S22, 0) -> 0 | AH15: =IF((M24=X15), S24, 0) -> 0 | AI15: =IF((M26=X15), S26, 0) -> 0 | AJ15: =IF((M29=X15), S29, 0) -> 0 | AK15: =IF((M31=X15), S31, 0) -> 0 | AL15: =IF((M33=X15), S33, 0) -> 0 | AM15: =IF((M35=X15), S35, 0) -> 0 | AN15: =IF((M38=X15), S38, 0) -> 0 | AO15: =IF((M40=X15), S40, 0) -> 0 | AP15: =IF((M42=X15), S42, 0) -> 0 | AQ15: =IF((M44=X15), S44, 0) -> 0 | AR15: =IF((M47=X15), S47, 0) -> 0 | AS15: =IF((M49=X15), S49, 0) -> 0 | AT15: =IF((M51=X15), S51, 0) -> 0 | AU15: =IF((M53=X15), S53, 0) -> 0 | AV15: =IF((M56=X15), S56, 0) -> 0 | AW15: =IF((M58=X15), S58, 0) -> 0 | AX15: =IF((M60=X15), S60, 0) -> 0 | AY15: =IF((M62=X15), S62, 0) -> 0 | AZ15: =IF((M65=X15), S65, 0) -> 0 | BA15: =IF((M67=X15), S67, 0) -> 0 | BB15: =IF((M69=X15), S69, 0) -> 0 | BC15: =IF((M71=X15), S71, 0) -> 0 | BD15: =IF((M74=X15), S74, 0) -> 0 | BE15: =IF((M76=X15), S76, 0) -> 0 | BF15: =IF((M78=X15), S78, 0) -> 0 | BG15: =IF((M80=X15), S80, 0) -> 0 | BH15: =IF((M83=X15), S83, 0) -> 0 | BI15: =IF((M85=X15), S85, 0) -> 0 | BJ15: =IF((M87=X15), S87, 0) -> 0 | BK15: =IF((M89=X15), S89, 0) -> 0 | BL15: =IF((M92=X15), S92, 0) -> 0 | BM15: =IF((M94=X15), S94, 0) -> 0 | BN15: =IF((M96=X15), S96, 0) -> 0 | BO15: =IF((M98=X15), S98, 0) -> 0 | BP15: =IF((M101=X15), S101, 0) -> 0 | BQ15: =IF((M103=X15), S103, 0) -> 0 | BR15: =IF((M105=X15), S105, 0) -> 0 | BS15: =IF((M107=X15), S107, 0) -> 0 | BT15: =IF((M110=X15), S110, 0) -> 0 | BU15: =IF((M112=X15), S112, 0) -> 0 | BV15: =IF((M114=X15), S114, 0) -> 0 | BW15: =IF((M116=X15), S116, 0) -> 0 | BX15: =IF((M119=X15), S119, 0) -> 0 | BY15: =IF((M121=X15), S121, 0) -> 0 | BZ15: =IF((M123=X15), S123, 0) -> 0 | CA15: =IF((M125=X15), S125, 0) -> 0 | CB15: =IF((M128=X15), S128, 0) -> 0 | CC15: =IF((M130=X15), S130, 0) -> 0 | CD15: =IF((M132=X15), S132, 0) -> 0 | CE15: =IF((M134=X15), S134, 0) -> 0 | CF15: =IF((M137=X15), S137, 0) -> 0 | CG15: =IF((M139=X15), S139, 0) -> 0 | CH15: =IF((M141=X15), S141, 0) -> 0 | CI15: =IF((M143=X15), S143, 0) -> 0 | CJ15: =IF((M146=X15), S146, 0) -> 0 | CK15: =IF((M148=X15), S148, 0) -> 0 | CL15: =IF((M150=X15), S150, 0) -> 0 | CM15: =IF((M152=X15), S152, 0) -> 0 | CN15: =IF((M155=X15), S155, 0) -> 0 | CO15: =IF((M157=X15), S157, 0) -> 0 | CP15: =IF((M159=X15), S159, 0) -> 0 | CQ15: =IF((M161=X15), S161, 0) -> 0 | CR15: =IF((M164=X15), S164, 0) -> 0 | CS15: =IF((M166=X15), S166, 0) -> 0 | CT15: =IF((M168=X15), S168, 0) -> 0 | CU15: =IF((M170=X15), S170, 0) -> 0 | CV15: =IF((M173=X15), S173, 0) -> 0 | CW15: =IF((M175=X15), S175, 0) -> 0 | CX15: =IF((M177=X15), S177, 0) -> 0 | CY15: =IF((M179=X15), S179, 0) -> 0 | CZ15: =IF((M182=X15), S182, 0) -> 0 | DA15: =IF((M184=X15), S184, 0) -> 0 | DB15: =IF((M186=X15), S186, 0) -> 0 | DC15: =IF((M188=X15), S188, 0) -> 0 | DD15: =IF((M191=X15), S191, 0) -> 0 | DE15: =IF((M193=X15), S193, 0) -> 0 | DF15: =IF((M195=X15), S195, 0) -> 0 | DG15: =IF((M197=X15), S197, 0) -> 0 | DH15: =IF((M200=X15), S200, 0) -> 0 | DI15: =IF((M202=X15), S202, 0) -> 0 | DJ15: =IF((M204=X15), S204, 0) -> 0 | DK15: =IF((M206=X15), S206, 0) -> 0 | DL15: =IF((M209=X15), S209, 0) -> 0 | DM15: =IF((M211=X15), S211, 0) -> 0 | DN15: =IF((M213=X15), S213, 0) -> 0 | DO15: =IF((M215=X15), S215, 0) -> 0 | DP15: =IF((M218=X15), S218, 0) -> 0 | DQ15: =IF((M220=X15), S220, 0) -> 0 | DR15: =IF((M222=X15), S222, 0) -> 0 | DS15: =IF((M224=X15), S224, 0) -> 0 | DT15: =IF((M227=X15), S227, 0) -> 0 | DU15: =IF((M229=X15), S229, 0) -> 0 | DV15: =IF((M231=X15), S231, 0) -> 0 | DW15: =IF((M233=X15), S233, 0) -> 0 | DX15: =IF((M236=X15), S236, 0) -> 0 | DY15: =IF((M238=X15), S238, 0) -> 0 | DZ15: =IF((M240=X15), S240, 0) -> 0 | EA15: =IF((M242=X15), S242, 0) -> 0 | EB15: =IF('NOME + Nº'!E62="SIM",0,IF((M259=X15),V259+IF(H259="SIM",IF((P259=X15),SUM(V260:V263), 0)), IF(H259="SIM",IF((P259=X15),SUM(V260:V263), 0)))) -> 0.22044444 | EC15: =IF('NOME + Nº'!E62="SIM",0,IF((M266=X15), V266+IF(H259="SIM",IF((P266=X15),SUM(V267:V270), 0)), IF(H259="SIM",IF((P266=X15),SUM(V267:V270), 0)))) -> 0.14666667 | ED15: =IF('NOME + Nº'!E62="SIM",0,IF((M273=X15), V273+IF(H259="SIM",IF((P273=X15),SUM(V274:V277), 0)), IF(H259="SIM",IF((P273=X15),SUM(V274:V277), 0)))) -> 0 | EE15: =IF('NOME + Nº'!E62="SIM",0,IF((M280=X15), V280+IF(H259="SIM",IF((P280=X15),SUM(V281:V284), 0)), IF(H259="SIM",IF((P280=X15),SUM(V281:V284), 0)))) -> 0 | EF15: =IF(AE33=X15,AE49,0) -> 0 | EG15: =IF('NOME + Nº'!D23="SIM",SUM(AB15:EF15),0) -> 0 | EI15: =SUM(EB15:EE15) -> 0.36711111
B16: Legendas | L16: =IF(K15="SIM","1","0") -> 1 | M16: =M14 -> 20 | R16: =O15/(Q15) -> 2.4013722 | W16: 3 | X16: ='NOME + Nº'!B24 -> Forro | Y16: ='NOME + Nº'!D37 -> Suede | Z16: ='NOME + Nº'!H37 -> 19.9 | AA16: ='NOME + Nº'!J37 -> 140 | AB16: =IF((M11=X16), S11, 0) -> 0 | AC16: =IF((M13=X16), S13, 0) -> 0 | AD16: =IF((M15=X16), S15, 0) -> 0 | AE16: =IF((M17=X16), S17, 0) -> 0 | AF16: =IF((M20=X16), S20, 0) -> 0 | AG16: =IF((M22=X16), S22, 0) -> 0 | AH16: =IF((M24=X16), S24, 0) -> 0 | AI16: =IF((M26=X16), S26, 0) -> 0 | AJ16: =IF((M29=X16), S29, 0) -> 0 | AK16: =IF((M31=X16), S31, 0) -> 0 | AL16: =IF((M33=X16), S33, 0) -> 0 | AM16: =IF((M35=X16), S35, 0) -> 0 | AN16: =IF((M38=X16), S38, 0) -> 0 | AO16: =IF((M40=X16), S40, 0) -> 0 | AP16: =IF((M42=X16), S42, 0) -> 0 | AQ16: =IF((M44=X16), S44, 0) -> 0 | AR16: =IF((M47=X16), S47, 0) -> 0 | AS16: =IF((M49=X16), S49, 0) -> 0 | AT16: =IF((M51=X16), S51, 0) -> 0 | AU16: =IF((M53=X16), S53, 0) -> 0 | AV16: =IF((M56=X16), S56, 0) -> 0 | AW16: =IF((M58=X16), S58, 0) -> 0 | AX16: =IF((M60=X16), S60, 0) -> 0 | AY16: =IF((M62=X16), S62, 0) -> 0 | AZ16: =IF((M65=X16), S65,0) -> 0 | BA16: =IF((M67=X16), S67, 0) -> 0 | BB16: =IF((M69=X16), S69, 0) -> 0 | BC16: =IF((M71=X16), S71, 0) -> 0 | BD16: =IF((M74=X16), S74, 0) -> 0 | BE16: =IF((M76=X16), S76, 0) -> 0 | BF16: =IF((M78=X16), S78, 0) -> 0 | BG16: =IF((M80=X16), S80, 0) -> 0 | BH16: =IF((M83=X16), S83, 0) -> 0 | BI16: =IF((M85=X16), S85, 0) -> 0 | BJ16: =IF((M87=X16), S87, 0) -> 0 | BK16: =IF((M89=X16), S89, 0) -> 0 | BL16: =IF((M92=X16), S92, 0) -> 0 | BM16: =IF((M94=X16), S94, 0) -> 0 | BN16: =IF((M96=X16), S96, 0) -> 0 | BO16: =IF((M98=X16), S98, 0) -> 0 | BP16: =IF((M101=X16), S101, 0) -> 0 | BQ16: =IF((M103=X16), S103, 0) -> 0 | BR16: =IF((M105=X16), S105, 0) -> 0 | BS16: =IF((M107=X16), S107, 0) -> 0 | BT16: =IF((M110=X16), S110, 0) -> 0 | BU16: =IF((M112=X16), S112, 0) -> 0 | BV16: =IF((M114=X16), S114, 0) -> 0 | BW16: =IF((M116=X16), S116, 0) -> 0 | BX16: =IF((M119=X16), S119, 0) -> 0 | BY16: =IF((M121=X16), S121, 0) -> 0 | BZ16: =IF((M123=X16), S123, 0) -> 0 | CA16: =IF((M125=X16), S125, 0) -> 0 | CB16: =IF((M128=X16), S128, 0) -> 0 | CC16: =IF((M130=X16), S130, 0) -> 0 | CD16: =IF((M132=X16), S132, 0) -> 0 | CE16: =IF((M134=X16), S134, 0) -> 0 | CF16: =IF((M137=X16), S137, 0) -> 0 | CG16: =IF((M139=X16), S139, 0) -> 0 | CH16: =IF((M141=X16), S141, 0) -> 0 | CI16: =IF((M143=X16), S143, 0) -> 0 | CJ16: =IF((M146=X16), S146, 0) -> 0 | CK16: =IF((M148=X16), S148, 0) -> 0 | CL16: =IF((M150=X16), S150, 0) -> 0 | CM16: =IF((M152=X16), S152, 0) -> 0 | CN16: =IF((M155=X16), S155, 0) -> 0 | CO16: =IF((M157=X16), S157, 0) -> 0 | CP16: =IF((M159=X16), S159, 0) -> 0 | CQ16: =IF((M161=X16), S161, 0) -> 0 | CR16: =IF((M164=X16), S164, 0) -> 0 | CS16: =IF((M166=X16), S166, 0) -> 0 | CT16: =IF((M168=X16), S168, 0) -> 0 | CU16: =IF((M170=X16), S170, 0) -> 0 | CV16: =IF((M173=X16), S173, 0) -> 0 | CW16: =IF((M175=X16), S175, 0) -> 0 | CX16: =IF((M177=X16), S177, 0) -> 0 | CY16: =IF((M179=X16), S179, 0) -> 0 | CZ16: =IF((M182=X16), S182, 0) -> 0 | DA16: =IF((M184=X16), S184, 0) -> 0 | DB16: =IF((M186=X16), S186, 0) -> 0 | DC16: =IF((M188=X16), S188, 0) -> 0 | DD16: =IF((M191=X16), S191, 0) -> 0 | DE16: =IF((M193=X16), S193, 0) -> 0 | DF16: =IF((M195=X16), S195, 0) -> 0 | DG16: =IF((M197=X16), S197, 0) -> 0 | DH16: =IF((M200=X16), S200, 0) -> 0 | DI16: =IF((M202=X16), S202, 0) -> 0 | DJ16: =IF((M204=X16), S204, 0) -> 0 | DK16: =IF((M206=X16), S206, 0) -> 0 | DL16: =IF((M209=X16), S209, 0) -> 0 | DM16: =IF((M211=X16), S211, 0) -> 0 | DN16: =IF((M213=X16), S213, 0) -> 0 | DO16: =IF((M215=X16), S215, 0) -> 0 | DP16: =IF((M218=X16), S218, 0) -> 0 | DQ16: =IF((M220=X16), S220, 0) -> 0 | DR16: =IF((M222=X16), S222, 0) -> 0 | DS16: =IF((M224=X16), S224, 0) -> 0 | DT16: =IF((M227=X16), S227, 0) -> 0 | DU16: =IF((M229=X16), S229, 0) -> 0 | DV16: =IF((M231=X16), S231, 0) -> 0 | DW16: =IF((M233=X16), S233, 0) -> 0 | DX16: =IF((M236=X16), S236, 0) -> 0 | DY16: =IF((M238=X16), S238, 0) -> 0 | DZ16: =IF((M240=X16), S240, 0) -> 0 | EA16: =IF((M242=X16), S242, 0) -> 0 | EB16: =IF('NOME + Nº'!E62="SIM",0,IF((M259=X16),V259+IF(H259="SIM",IF((P259=X16),SUM(V260:V263), 0)), IF(H259="SIM",IF((P259=X16),SUM(V260:V263), 0)))) -> 0 | EC16: =IF('NOME + Nº'!E62="SIM",0,IF((M266=X16), V266+IF(H259="SIM",IF((P266=X16),SUM(V267:V270), 0)), IF(H259="SIM",IF((P266=X16),SUM(V267:V270), 0)))) -> 0 | ED16: =IF('NOME + Nº'!E62="SIM",0,IF((M273=X16), V273+IF(H259="SIM",IF((P273=X16),SUM(V274:V277), 0)), IF(H259="SIM",IF((P273=X16),SUM(V274:V277), 0)))) -> 0 | EE16: =IF('NOME + Nº'!E62="SIM",0,IF((M280=X16), V280+IF(H259="SIM",IF((P280=X16),SUM(V281:V284), 0)), IF(H259="SIM",IF((P280=X16),SUM(V281:V284), 0)))) -> 0 | EF16: =IF(AE33=X16,AE49,0) -> 0 | EG16: =IF('NOME + Nº'!D24="SIM",SUM(AB16:EF16),0) -> 0 | EI16: =SUM(EB16:EE16) -> 0
B17: No rótulo do PROCESSO, escolha as opções para sinalizar uso do quadro | F17: SIM | J17: =J15+1 -> 4 | K17: NÃO | L17: 1 | M17: Reforço | N17: =IF((M17=X14),Z14,(IF((M17=X15),Z15,(IF((M17=X16),Z16,(IF((M17=X17),Z17,(IF((M17=X18),Z18,(IF((M17=X19),Z19,(IF((M17=X20),Z20))))))))))))) -> 7.9 | O17: =IF((M17=X14),AA14,(IF((M17=X15),AA15,(IF((M17=X16),AA16,(IF((M17=X17),AA17,(IF((M17=X18),AA18,(IF((M17=X19),AA19,(IF((M17=X20),AA20))))))))))))) -> 140 | P17: =P15 -> 34.4 | Q17: =Q15 -> 58.3 | R17: =IF(R19<(M19*L17), INT(R19),(M19*L17)) -> 2 | S17: =IF(K17="SIM",(N17*L17*(P17/100)/R17)*L19,0) -> 0 | T17: =R19*L19 -> 0 | W17: 4 | X17: ='NOME + Nº'!B25 -> Couro | Y17: ='NOME + Nº'!D38 -> Couro Legítimo Fly | Z17: ='NOME + Nº'!H38 -> 74.9 | AA17: ='NOME + Nº'!J38 -> 100 | AB17: =IF((M11=X17), S11, 0) -> 0 | AC17: =IF((M13=X17), S13, 0) -> 0 | AD17: =IF((M15=X17), S15, 0) -> 0 | AE17: =IF((M17=X17), S17, 0) -> 0 | AF17: =IF((M20=X17), S20, 0) -> 0 | AG17: =IF((M22=X17), S22, 0) -> 0 | AH17: =IF((M24=X17), S24, 0) -> 0 | AI17: =IF((M26=X17), S26, 0) -> 0 | AJ17: =IF((M29=X17), S29, 0) -> 0 | AK17: =IF((M31=X17), S31, 0) -> 0 | AL17: =IF((M33=X17), S33, 0) -> 0 | AM17: =IF((M35=X17), S35, 0) -> 0 | AN17: =IF((M38=X17), S38, 0) -> 0 | AO17: =IF((M40=X17), S40, 0) -> 0 | AP17: =IF((M42=X17), S42, 0) -> 0 | AQ17: =IF((M44=X17), S44, 0) -> 0 | AR17: =IF((M47=X17), S47, 0) -> 0 | AS17: =IF((M49=X17), S49, 0) -> 0 | AT17: =IF((M51=X17), S51, 0) -> 0 | AU17: =IF((M53=X17), S53, 0) -> 0 | AV17: =IF((M56=X17), S56, 0) -> 0 | AW17: =IF((M58=X17), S58, 0) -> 0 | AX17: =IF((M60=X17), S60, 0) -> 0 | AY17: =IF((M62=X17), S62, 0) -> 0 | AZ17: =IF((M65=X17), S65, 0) -> 0 | BA17: =IF((M67=X17), S67, 0) -> 0 | BB17: =IF((M69=X17), S69, 0) -> 0 | BC17: =IF((M71=X17), S71, 0) -> 0 | BD17: =IF((M74=X17), S74, 0) -> 0 | BE17: =IF((M76=X17), S76, 0) -> 0 | BF17: =IF((M78=X17), S78, 0) -> 0 | BG17: =IF((M80=X17), S80, 0) -> 0 | BH17: =IF((M83=X17), S83, 0) -> 0 | BI17: =IF((M85=X17), S85, 0) -> 0 | BJ17: =IF((M87=X17), S87, 0) -> 0 | BK17: =IF((M89=X17), S89, 0) -> 0 | BL17: =IF((M92=X17), S92, 0) -> 0 | BM17: =IF((M94=X17), S94, 0) -> 0 | BN17: =IF((M96=X17), S96, 0) -> 0 | BO17: =IF((M98=X17), S98, 0) -> 0 | BP17: =IF((M101=X17), S101, 0) -> 0 | BQ17: =IF((M103=X17), S103, 0) -> 0 | BR17: =IF((M105=X17), S105, 0) -> 0 | BS17: =IF((M107=X17), S107, 0) -> 0 | BT17: =IF((M110=X17), S110, 0) -> 0 | BU17: =IF((M112=X17), S112, 0) -> 0 | BV17: =IF((M114=X17), S114, 0) -> 0 | BW17: =IF((M116=X17), S116, 0) -> 0 | BX17: =IF((M119=X17), S119, 0) -> 0 | BY17: =IF((M121=X17), S121, 0) -> 0 | BZ17: =IF((M123=X17), S123, 0) -> 0 | CA17: =IF((M125=X17), S125, 0) -> 0 | CB17: =IF((M128=X17), S128, 0) -> 0 | CC17: =IF((M130=X17), S130, 0) -> 0 | CD17: =IF((M132=X17), S132, 0) -> 0 | CE17: =IF((M134=X17), S134, 0) -> 0 | CF17: =IF((M137=X17), S137, 0) -> 0 | CG17: =IF((M139=X17), S139, 0) -> 0 | CH17: =IF((M141=X17), S141, 0) -> 0 | CI17: =IF((M143=X17), S143, 0) -> 0 | CJ17: =IF((M146=X17), S146, 0) -> 0 | CK17: =IF((M148=X17), S148, 0) -> 0 | CL17: =IF((M150=X17), S150, 0) -> 0 | CM17: =IF((M152=X17), S152, 0) -> 0 | CN17: =IF((M155=X17), S155, 0) -> 0 | CO17: =IF((M157=X17), S157, 0) -> 0 | CP17: =IF((M159=X17), S159, 0) -> 0 | CQ17: =IF((M161=X17), S161, 0) -> 0 | CR17: =IF((M164=X17), S164, 0) -> 0 | CS17: =IF((M166=X17), S166, 0) -> 0 | CT17: =IF((M168=X17), S168, 0) -> 0 | CU17: =IF((M170=X17), S170, 0) -> 0 | CV17: =IF((M173=X17), S173, 0) -> 0 | CW17: =IF((M175=X17), S175, 0) -> 0 | CX17: =IF((M177=X17), S177, 0) -> 0 | CY17: =IF((M179=X17), S179, 0) -> 0 | CZ17: =IF((M182=X17), S182, 0) -> 0 | DA17: =IF((M184=X17), S184, 0) -> 0 | DB17: =IF((M186=X17), S186, 0) -> 0 | DC17: =IF((M188=X17), S188, 0) -> 0 | DD17: =IF((M191=X17), S191, 0) -> 0 | DE17: =IF((M193=X17), S193, 0) -> 0 | DF17: =IF((M195=X17), S195, 0) -> 0 | DG17: =IF((M197=X17), S197, 0) -> 0 | DH17: =IF((M200=X17), S200, 0) -> 0 | DI17: =IF((M202=X17), S202, 0) -> 0 | DJ17: =IF((M204=X17), S204, 0) -> 0 | DK17: =IF((M206=X17), S206, 0) -> 0 | DL17: =IF((M209=X17), S209, 0) -> 0 | DM17: =IF((M211=X17), S211, 0) -> 0 | DN17: =IF((M213=X17), S213, 0) -> 0 | DO17: =IF((M215=X17), S215, 0) -> 0 | DP17: =IF((M218=X17), S218, 0) -> 0 | DQ17: =IF((M220=X17), S220, 0) -> 0 | DR17: =IF((M222=X17), S222, 0) -> 0 | DS17: =IF((M224=X17), S224, 0) -> 0 | DT17: =IF((M227=X17), S227, 0) -> 0 | DU17: =IF((M229=X17), S229, 0) -> 0 | DV17: =IF((M231=X17), S231, 0) -> 0 | DW17: =IF((M233=X17), S233, 0) -> 0 | DX17: =IF((M236=X17), S236, 0) -> 0 | DY17: =IF((M238=X17), S238, 0) -> 0 | DZ17: =IF((M240=X17), S240, 0) -> 0 | EA17: =IF((M242=X17), S242, 0) -> 0 | EB17: =IF('NOME + Nº'!E62="SIM",0,IF((M259=X17),V259+IF(H259="SIM",IF((P259=X17),SUM(V260:V263), 0)), IF(H259="SIM",IF((P259=X17),SUM(V260:V263), 0)))) -> 0 | EC17: =IF('NOME + Nº'!E62="SIM",0,IF((M266=X17), V266+IF(H259="SIM",IF((P266=X17),SUM(V267:V270), 0)), IF(H259="SIM",IF((P266=X17),SUM(V267:V270), 0)))) -> 0 | ED17: =IF('NOME + Nº'!E62="SIM",0,IF((M273=X17), V273+IF(H259="SIM",IF((P273=X17),SUM(V274:V277), 0)), IF(H259="SIM",IF((P273=X17),SUM(V274:V277), 0)))) -> 0 | EE17: =IF('NOME + Nº'!E62="SIM",0,IF((M280=X17), V280+IF(H259="SIM",IF((P280=X17),SUM(V281:V284), 0)), IF(H259="SIM",IF((P280=X17),SUM(V281:V284), 0)))) -> 0 | EF17: =IF(AE33=X17,AE49,0) -> 0 | EG17: =IF('NOME + Nº'!D25="SIM",SUM(AB17:EF17),0) -> 0 | EI17: =SUM(EB17:EE17) -> 0
F18: NÃO | H18: Obs | W18: 5 | X18: ='NOME + Nº'!B26 -> Tec. Vivo | Y18: ='NOME + Nº'!D39 -> Aquablock | Z18: ='NOME + Nº'!H39 -> 49.9 | AA18: ='NOME + Nº'!J39 -> 140 | AB18: =IF((M11=X18), S11, 0) -> 0 | AC18: =IF((M13=X18), S13, 0) -> 0 | AD18: =IF((M15=X18), S15, 0) -> 0 | AE18: =IF((M17=X18), S17, 0) -> 0 | AF18: =IF((M20=X18), S20, 0) -> 0 | AG18: =IF((M22=X18), S22, 0) -> 0 | AH18: =IF((M24=X18), S24, 0) -> 0 | AI18: =IF((M26=X18), S26, 0) -> 0 | AJ18: =IF((M29=X18), S29, 0) -> 0 | AK18: =IF((M31=X18), S31, 0) -> 0 | AL18: =IF((M33=X18), S33, 0) -> 0 | AM18: =IF((M35=X18), S35, 0) -> 0 | AN18: =IF((M38=X18), S38, 0) -> 0 | AO18: =IF((M40=X18), S40, 0) -> 0 | AP18: =IF((M42=X18), S42, 0) -> 0 | AQ18: =IF((M44=X18), S44, 0) -> 0 | AR18: =IF((M47=X18), S47, 0) -> 0 | AS18: =IF((M49=X18), S49, 0) -> 0 | AT18: =IF((M51=X18), S51, 0) -> 0 | AU18: =IF((M53=X18), S53, 0) -> 0 | AV18: =IF((M56=X18), S56, 0) -> 0 | AW18: =IF((M58=X18), S58, 0) -> 0 | AX18: =IF((M60=X18), S60, 0) -> 0 | AY18: =IF((M62=X18), S62, 0) -> 0 | AZ18: =IF((M65=X18), S65, 0) -> 0 | BA18: =IF((M67=X18), S67, 0) -> 0 | BB18: =IF((M69=X18), S69, 0) -> 0 | BC18: =IF((M71=X18), S71, 0) -> 0 | BD18: =IF((M74=X18), S74, 0) -> 0 | BE18: =IF((M76=X18), S76, 0) -> 0 | BF18: =IF((M78=X18), S78, 0) -> 0 | BG18: =IF((M80=X18), S80, 0) -> 0 | BH18: =IF((M83=X18), S83, 0) -> 0 | BI18: =IF((M85=X18), S85, 0) -> 0 | BJ18: =IF((M87=X18), S87, 0) -> 0 | BK18: =IF((M89=X18), S89, 0) -> 0 | BL18: =IF((M92=X18), S92, 0) -> 0 | BM18: =IF((M94=X18), S94, 0) -> 0 | BN18: =IF((M96=X18), S96, 0) -> 0 | BO18: =IF((M98=X18), S98, 0) -> 0 | BP18: =IF((M101=X18), S101, 0) -> 0 | BQ18: =IF((M103=X18), S103, 0) -> 0 | BR18: =IF((M105=X18), S105, 0) -> 0 | BS18: =IF((M107=X18), S107, 0) -> 0 | BT18: =IF((M110=X18), S110, 0) -> 0 | BU18: =IF((M112=X18), S112, 0) -> 0 | BV18: =IF((M114=X18), S114, 0) -> 0 | BW18: =IF((M116=X18), S116, 0) -> 0 | BX18: =IF((M119=X18), S119, 0) -> 0 | BY18: =IF((M121=X18), S121, 0) -> 0 | BZ18: =IF((M123=X18), S123, 0) -> 0 | CA18: =IF((M125=X18), S125, 0) -> 0 | CB18: =IF((M128=X18), S128, 0) -> 0 | CC18: =IF((M130=X18), S130, 0) -> 0 | CD18: =IF((M132=X18), S132, 0) -> 0 | CE18: =IF((M134=X18), S134, 0) -> 0 | CF18: =IF((M137=X18), S137, 0) -> 0 | CG18: =IF((M139=X18), S139, 0) -> 0 | CH18: =IF((M141=X18), S141, 0) -> 0 | CI18: =IF((M143=X18), S143, 0) -> 0 | CJ18: =IF((M146=X18), S146, 0) -> 0 | CK18: =IF((M148=X18), S148, 0) -> 0 | CL18: =IF((M150=X18), S150, 0) -> 0 | CM18: =IF((M152=X18), S152, 0) -> 0 | CN18: =IF((M155=X18), S155, 0) -> 0 | CO18: =IF((M157=X18), S157, 0) -> 0 | CP18: =IF((M159=X18), S159, 0) -> 0 | CQ18: =IF((M161=X18), S161, 0) -> 0 | CR18: =IF((M164=X18), S164, 0) -> 0 | CS18: =IF((M166=X18), S166, 0) -> 0 | CT18: =IF((M168=X18), S168, 0) -> 0 | CU18: =IF((M170=X18), S170, 0) -> 0 | CV18: =IF((M173=X18), S173, 0) -> 0 | CW18: =IF((M175=X18), S175, 0) -> 0 | CX18: =IF((M177=X18), S177, 0) -> 0 | CY18: =IF((M179=X18), S179, 0) -> 0 | CZ18: =IF((M182=X18), S182, 0) -> 0 | DA18: =IF((M184=X18), S184, 0) -> 0 | DB18: =IF((M186=X18), S186, 0) -> 0 | DC18: =IF((M188=X18), S188, 0) -> 0 | DD18: =IF((M191=X18), S191, 0) -> 0 | DE18: =IF((M193=X18), S193, 0) -> 0 | DF18: =IF((M195=X18), S195, 0) -> 0 | DG18: =IF((M197=X18), S197, 0) -> 0 | DH18: =IF((M200=X18), S200, 0) -> 0 | DI18: =IF((M202=X18), S202, 0) -> 0 | DJ18: =IF((M204=X18), S204, 0) -> 0 | DK18: =IF((M206=X18), S206, 0) -> 0 | DL18: =IF((M209=X18), S209, 0) -> 0 | DM18: =IF((M211=X18), S211, 0) -> 0 | DN18: =IF((M213=X18), S213, 0) -> 0 | DO18: =IF((M215=X18), S215, 0) -> 0 | DP18: =IF((M218=X18), S218, 0) -> 0 | DQ18: =IF((M220=X18), S220, 0) -> 0 | DR18: =IF((M222=X18), S222, 0) -> 0 | DS18: =IF((M224=X18), S224, 0) -> 0 | DT18: =IF((M227=X18), S227, 0) -> 0 | DU18: =IF((M229=X18), S229, 0) -> 0 | DV18: =IF((M231=X18), S231, 0) -> 0 | DW18: =IF((M233=X18), S233, 0) -> 0 | DX18: =IF((M236=X18), S236, 0) -> 0 | DY18: =IF((M238=X18), S238, 0) -> 0 | DZ18: =IF((M240=X18), S240, 0) -> 0 | EA18: =IF((M242=X18), S242, 0) -> 0 | EB18: =IF('NOME + Nº'!E62="SIM",0,IF((M259=X18),V259+IF(H259="SIM",IF((P259=X18),SUM(V260:V263), 0)), IF(H259="SIM",IF((P259=X18),SUM(V260:V263), 0)))) -> 0 | EC18: =IF('NOME + Nº'!E62="SIM",0,IF((M266=X18), V266+IF(H259="SIM",IF((P266=X18),SUM(V267:V270), 0)), IF(H259="SIM",IF((P266=X18),SUM(V267:V270), 0)))) -> 0 | ED18: =IF('NOME + Nº'!E62="SIM",0,IF((M273=X18), V273+IF(H259="SIM",IF((P273=X18),SUM(V274:V277), 0)), IF(H259="SIM",IF((P273=X18),SUM(V274:V277), 0)))) -> 0 | EE18: =IF('NOME + Nº'!E62="SIM",0,IF((M280=X18), V280+IF(H259="SIM",IF((P280=X18),SUM(V281:V284), 0)), IF(H259="SIM",IF((P280=X18),SUM(V281:V284), 0)))) -> 0 | EF18: =IF(AE33=X18,AE49,0) -> 0 | EG18: =IF('NOME + Nº'!D26="SIM",SUM(AB18:EF18),0) -> 0 | EI18: =SUM(EB18:EE18) -> 0
B19: Escreva os FORNECEDORES nos quadros de Materiais com LETRAS MAIÚSCULAS. Escrever materiais iniciando com letras MAIÚSCULAS. | L19: =IF(K17="SIM","1","0") -> 0 | M19: =M16 -> 20 | R19: =O17/(Q17) -> 2.4013722 | W19: 6 | X19: ='NOME + Nº'!B27 -> Estrutura | Y19: ='NOME + Nº'!D40 -> Placa Plástica | Z19: ='NOME + Nº'!H40 -> 20.12 | AA19: ='NOME + Nº'!J40 -> 28 | AB19: =IF((M11=X19), S11, 0) -> 0 | AC19: =IF((M13=X19), S13, 0) -> 0 | AD19: =IF((M15=X19), S15, 0) -> 0 | AE19: =IF((M17=X19), S17, 0) -> 0 | AF19: =IF((M20=X19), S20, 0) -> 0 | AG19: =IF((M22=X19), S22, 0) -> 0 | AH19: =IF((M24=X19), S24, 0) -> 0 | AI19: =IF((M26=X19), S26, 0) -> 0 | AJ19: =IF((M29=X19), S29, 0) -> 0 | AK19: =IF((M31=X19), S31, 0) -> 0 | AL19: =IF((M33=X19), S33, 0) -> 0 | AM19: =IF((M35=X19), S35, 0) -> 0 | AN19: =IF((M38=X19), S38, 0) -> 0 | AO19: =IF((M40=X19), S40, 0) -> 0 | AP19: =IF((M42=X19), S42, 0) -> 0 | AQ19: =IF((M44=X19), S44, 0) -> 0 | AR19: =IF((M47=X19), S47, 0) -> 0 | AS19: =IF((M49=X19), S49, 0) -> 0 | AT19: =IF((M51=X19), S51, 0) -> 0 | AU19: =IF((M53=X19), S53, 0) -> 0 | AV19: =IF((M56=X19), S56, 0) -> 0 | AW19: =IF((M58=X19), S58, 0) -> 0 | AX19: =IF((M60=X19), S60, 0) -> 0 | AY19: =IF((M62=X19), S62, 0) -> 0 | AZ19: =IF((M65=X19), S65, 0) -> 0 | BA19: =IF((M67=X19), S67, 0) -> 0 | BB19: =IF((M69=X19), S69, 0) -> 0 | BC19: =IF((M71=X19), S71, 0) -> 0 | BD19: =IF((M74=X19), S74, 0) -> 0 | BE19: =IF((M76=X19), S76, 0) -> 0 | BF19: =IF((M78=X19), S78, 0) -> 0 | BG19: =IF((M80=X19), S80, 0) -> 0 | BH19: =IF((M83=X19), S83, 0) -> 0 | BI19: =IF((M85=X19), S85, 0) -> 0 | BJ19: =IF((M87=X19), S87, 0) -> 0 | BK19: =IF((M89=X19), S89, 0) -> 0 | BL19: =IF((M92=X19), S92, 0) -> 0 | BM19: =IF((M94=X19), S94, 0) -> 0 | BN19: =IF((M96=X19), S96, 0) -> 0 | BO19: =IF((M98=X19), S98, 0) -> 0 | BP19: =IF((M101=X19), S101, 0) -> 0 | BQ19: =IF((M103=X19), S103, 0) -> 0 | BR19: =IF((M105=X19), S105, 0) -> 0 | BS19: =IF((M107=X19), S107, 0) -> 0 | BT19: =IF((M110=X19), S110, 0) -> 0 | BU19: =IF((M112=X19), S112, 0) -> 0 | BV19: =IF((M114=X19), S114, 0) -> 0 | BW19: =IF((M116=X19), S116, 0) -> 0 | BX19: =IF((M119=X19), S119, 0) -> 0 | BY19: =IF((M121=X19), S121, 0) -> 0 | BZ19: =IF((M123=X19), S123, 0) -> 0 | CA19: =IF((M125=X19), S125, 0) -> 0 | CB19: =IF((M128=X19),S128, 0) -> 0 | CC19: =IF((M130=X19), S130, 0) -> 0 | CD19: =IF((M132=X19), S132, 0) -> 0 | CE19: =IF((M134=X19), S134, 0) -> 0 | CF19: =IF((M137=X19), S137, 0) -> 0 | CG19: =IF((M139=X19), S139, 0) -> 0 | CH19: =IF((M141=X19), S141, 0) -> 0 | CI19: =IF((M143=X19), S143, 0) -> 0 | CJ19: =IF((M146=X19), S146, 0) -> 0 | CK19: =IF((M148=X19), S148, 0) -> 0 | CL19: =IF((M150=X19), S150, 0) -> 0 | CM19: =IF((M152=X19), S152, 0) -> 0 | CN19: =IF((M155=X19), S155, 0) -> 0 | CO19: =IF((M157=X19), S157, 0) -> 0 | CP19: =IF((M159=X19), S159, 0) -> 0 | CQ19: =IF((M161=X19), S161, 0) -> 0 | CR19: =IF((M164=X19), S164, 0) -> 0 | CS19: =IF((M166=X19), S166, 0) -> 0 | CT19: =IF((M168=X19), S168, 0) -> 0 | CU19: =IF((M170=X19), S170, 0) -> 0 | CV19: =IF((M173=X19), S173, 0) -> 0 | CW19: =IF((M175=X19), S175, 0) -> 0 | CX19: =IF((M177=X19), S177, 0) -> 0 | CY19: =IF((M179=X19), S179, 0) -> 0 | CZ19: =IF((M182=X19), S182, 0) -> 0 | DA19: =IF((M184=X19), S184, 0) -> 0 | DB19: =IF((M186=X19), S186, 0) -> 0 | DC19: =IF((M188=X19), S188, 0) -> 0 | DD19: =IF((M191=X19), S191, 0) -> 0 | DE19: =IF((M193=X19), S193, 0) -> 0 | DF19: =IF((M195=X19), S195, 0) -> 0 | DG19: =IF((M197=X19), S197, 0) -> 0 | DH19: =IF((M200=X19), S200, 0) -> 0 | DI19: =IF((M202=X19), S202, 0) -> 0 | DJ19: =IF((M204=X19), S204, 0) -> 0 | DK19: =IF((M206=X19), S206, 0) -> 0 | DL19: =IF((M209=X19), S209, 0) -> 0 | DM19: =IF((M211=X19), S211, 0) -> 0 | DN19: =IF((M213=X19), S213, 0) -> 0 | DO19: =IF((M215=X19), S215, 0) -> 0 | DP19: =IF((M218=X19), S218, 0) -> 0 | DQ19: =IF((M220=X19), S220, 0) -> 0 | DR19: =IF((M222=X19), S222, 0) -> 0 | DS19: =IF((M224=X19), S224, 0) -> 0 | DT19: =IF((M227=X19), S227, 0) -> 0 | DU19: =IF((M229=X19), S229, 0) -> 0 | DV19: =IF((M231=X19), S231, 0) -> 0 | DW19: =IF((M233=X19), S233, 0) -> 0 | DX19: =IF((M236=X19), S236, 0) -> 0 | DY19: =IF((M238=X19), S238, 0) -> 0 | DZ19: =IF((M240=X19), S240, 0) -> 0 | EA19: =IF((M242=X19), S242, 0) -> 0 | EB19: =IF('NOME + Nº'!E62="SIM",0,IF((M259=X19),V259+IF(H259="SIM",IF((P259=X19),SUM(V260:V263), 0)), IF(H259="SIM",IF((P259=X19),SUM(V260:V263), 0)))) -> 0 | EC19: =IF('NOME + Nº'!E62="SIM",0,IF((M266=X19), V266+IF(H259="SIM",IF((P266=X19),SUM(V267:V270), 0)), IF(H259="SIM",IF((P266=X19),SUM(V267:V270), 0)))) -> 0 | ED19: =IF('NOME + Nº'!E62="SIM",0,IF((M273=X19), V273+IF(H259="SIM",IF((P273=X19),SUM(V274:V277), 0)), IF(H259="SIM",IF((P273=X19),SUM(V274:V277), 0)))) -> 0 | EE19: =IF('NOME + Nº'!E62="SIM",0,IF((M280=X19), V280+IF(H259="SIM",IF((P280=X19),SUM(V281:V284), 0)), IF(H259="SIM",IF((P280=X19),SUM(V281:V284), 0)))) -> 0 | EF19: =IF(AE33=X19,AE49,0) -> 0 | EG19: =IF('NOME + Nº'!D27="SIM",SUM(AB19:EF19),0) -> 0 | EI19: =SUM(EB19:EE19) -> 0
G20: =G11+1 -> 2 | H20: =CONCATENATE("MOLDE ",G20) -> MOLDE 2 | J20: =J17+1 -> 5 | K20: NÃO | L20: 1 | M20: Tec. Externo | N20: =IF((M20=X14),Z14,(IF((M20=X15),Z15,(IF((M20=X16),Z16,(IF((M20=X17),Z17,(IF((M20=X18),Z18,(IF((M20=X19),Z19,(IF((M20=X20),Z20))))))))))))) -> 49.9 | O20: =IF((M20=X14),AA14,(IF((M20=X15),AA15,(IF((M20=X16),AA16,(IF((M20=X17),AA17,(IF((M20=X18),AA18,(IF((M20=X19),AA19,(IF((M20=X20),AA20))))))))))))) -> 140 | P20: =2*Z34+Z33+2*Z38 -> 21.4 | Q20: =(Z32-1)+1.5*Z37 -> 15.5 | R20: =IF(R21<(M21*L20), INT(R21),(M21*L20)) -> 9 | S20: =IF(K20="SIM",(N20*L20*(P20/100)/R20)*L21,0) -> 0 | T20: =R21*L21 -> 0 | U20: =IF(K20="SIM",1,IF(K22="SIM",1,IF(K24="SIM",1,IF(K26="SIM",1,0)))) -> 0 | W20: 7 (NOVO) | X20: ='NOME + Nº'!B28 -> Reforço | Y20: ='NOME + Nº'!D41 -> TNT 120 | Z20: ='NOME + Nº'!H41 -> 7.9 | AA20: ='NOME + Nº'!J41 -> 140 | AB20: =IF((M11=X20), S11, 0) -> 0 | AC20: =IF((M13=X20), S13, 0) -> 1.3588 | AD20: =IF((M15=X20), S15, 0) -> 1.3588 | AE20: =IF((M17=X20), S17, 0) -> 0 | AF20: =IF((M20=X20), S20, 0) -> 0 | AG20: =IF((M22=X20), S22, 0) -> 0 | AH20: =IF((M24=X20), S24, 0) -> 0 | AI20: =IF((M26=X20), S26, 0) -> 0 | AJ20: =IF((M29=X20), S29, 0) -> 0 | AK20: =IF((M31=X20), S31, 0) -> 0 | AL20: =IF((M33=X20), S33, 0) -> 0 | AM20: =IF((M35=X20), S35, 0) -> 0 | AN20: =IF((M38=X20), S38, 0) -> 0 | AO20: =IF((M40=X20), S40, 0) -> 0 | AP20: =IF((M42=X20), S42, 0) -> 0 | AQ20: =IF((M44=X20), S44, 0) -> 0 | AR20: =IF((M47=X20), S47, 0) -> 0 | AS20: =IF((M49=X20), S49, 0) -> 0 | AT20: =IF((M51=X20), S51, 0) -> 0 | AU20: =IF((M53=X20), S53, 0) -> 0 | AV20: =IF((M56=X20), S56, 0) -> 0 | AW20: =IF((M58=X20), S58, 0) -> 0 | AX20: =IF((M60=X20), S60, 0) -> 0 | AY20: =IF((M62=X20), S62, 0) -> 0 | AZ20: =IF((M65=X20), S65, 0) -> 0 | BA20: =IF((M67=X20), S67, 0) -> 0 | BB20: =IF((M69=X20), S69, 0) -> 0 | BC20: =IF((M71=X20), S71, 0) -> 0 | BD20: =IF((M74=X20), S74, 0) -> 0 | BE20: =IF((M76=X20), S76, 0) -> 0 | BF20: =IF((M78=X20), S78, 0) -> 0 | BG20: =IF((M80=X20), S80, 0) -> 0 | BH20: =IF((M83=X20), S83, 0) -> 0 | BI20: =IF((M85=X20), S85, 0) -> 0 | BJ20: =IF((M87=X20), S87, 0) -> 0 | BK20: =IF((M89=X20), S89, 0) -> 0 | BL20: =IF((M92=X20), S92, 0) -> 0 | BM20: =IF((M94=X20), S94, 0) -> 0 | BN20: =IF((M96=X20), S96, 0) -> 0 | BO20: =IF((M98=X20), S98, 0) -> 0 | BP20: =IF((M101=X20), S101, 0) -> 0 | BQ20: =IF((M103=X20), S103, 0) -> 0 | BR20: =IF((M105=X20), S105, 0) -> 0 | BS20: =IF((M107=X20), S107, 0) -> 0 | BT20: =IF((M110=X20), S110, 0) -> 0 | BU20: =IF((M112=X20), S112, 0) -> 0 | BV20: =IF((M114=X20), S114, 0) -> 0 | BW20: =IF((M116=X20), S116, 0) -> 0 | BX20: =IF((M119=X20), S119, 0) -> 0 | BY20: =IF((M121=X20), S121, 0) -> 0 | BZ20: =IF((M123=X20), S123, 0) -> 0 | CA20: =IF((M125=X20), S125, 0) -> 0 | CB20: =IF((M128=X20),S128, 0) -> 0 | CC20: =IF((M130=X20), S130, 0) -> 0 | CD20: =IF((M132=X20), S132, 0) -> 0 | CE20: =IF((M134=X20), S134, 0) -> 0 | CF20: =IF((M137=X20), S137, 0) -> 0 | CG20: =IF((M139=X20), S139, 0) -> 0 | CH20: =IF((M141=X20), S141, 0) -> 0 | CI20: =IF((M143=X20), S143, 0) -> 0 | CJ20: =IF((M146=X20), S146, 0) -> 0 | CK20: =IF((M148=X20), S148, 0) -> 0 | CL20: =IF((M150=X20), S150, 0) -> 0 | CM20: =IF((M152=X20), S152, 0) -> 0 | CN20: =IF((M155=X20), S155, 0) -> 0 | CO20: =IF((M157=X20), S157, 0) -> 0 | CP20: =IF((M159=X20), S159, 0) -> 0 | CQ20: =IF((M161=X20), S161, 0) -> 0 | CR20: =IF((M164=X20), S164, 0) -> 0 | CS20: =IF((M166=X20), S166, 0) -> 0 | CT20: =IF((M168=X20), S168, 0) -> 0 | CU20: =IF((M170=X20), S170, 0) -> 0 | CV20: =IF((M173=X20), S173, 0) -> 0 | CW20: =IF((M175=X20), S175, 0) -> 0 | CX20: =IF((M177=X20), S177, 0) -> 0 | CY20: =IF((M179=X20), S179, 0) -> 0 | CZ20: =IF((M182=X20), S182, 0) -> 0 | DA20: =IF((M184=X20), S184, 0) -> 0 | DB20: =IF((M186=X20), S186, 0) -> 0 | DC20: =IF((M188=X20), S188, 0) -> 0 | DD20: =IF((M191=X20), S191, 0) -> 0 | DE20: =IF((M193=X20), S193, 0) -> 0 | DF20: =IF((M195=X20), S195, 0) -> 0 | DG20: =IF((M197=X20), S197, 0) -> 0 | DH20: =IF((M200=X20), S200, 0) -> 0 | DI20: =IF((M202=X20), S202, 0) -> 0 | DJ20: =IF((M204=X20), S204, 0) -> 0 | DK20: =IF((M206=X20), S206, 0) -> 0 | DL20: =IF((M209=X20), S209, 0) -> 0 | DM20: =IF((M211=X20), S211, 0) -> 0 | DN20: =IF((M213=X20), S213, 0) -> 0 | DO20: =IF((M215=X20), S215, 0) -> 0 | DP20: =IF((M218=X20), S218, 0) -> 0 | DQ20: =IF((M220=X20), S220, 0) -> 0 | DR20: =IF((M222=X20), S222, 0) -> 0 | DS20: =IF((M224=X20), S224, 0) -> 0 | DT20: =IF((M227=X20), S227, 0) -> 0 | DU20: =IF((M229=X20), S229, 0) -> 0 | DV20: =IF((M231=X20), S231, 0) -> 0 | DW20: =IF((M233=X20), S233, 0) -> 0 | DX20: =IF((M236=X20), S236, 0) -> 0 | DY20: =IF((M238=X20), S238, 0) -> 0 | DZ20: =IF((M240=X20), S240, 0) -> 0 | EA20: =IF((M242=X20), S242, 0) -> 0 | EB20: =IF('NOME + Nº'!E62="SIM",0,IF((M259=X20),V259+IF(H259="SIM",IF((P259=X20),SUM(V260:V263), 0)), IF(H259="SIM",IF((P259=X20),SUM(V260:V263), 0)))) -> 0 | EC20: =IF('NOME + Nº'!E62="SIM",0,IF((M266=X20), V266+IF(H259="SIM",IF((P266=X20),SUM(V267:V270), 0)), IF(H259="SIM",IF((P266=X20),SUM(V267:V270), 0)))) -> 0 | ED20: =IF('NOME + Nº'!E62="SIM",0,IF((M273=X14), V273+IF(H259="SIM",IF((P273=X20),SUM(V274:V277), 0)), IF(H259="SIM",IF((P273=X20),SUM(V274:V277), 0)))) -> 0 | EE20: =IF('NOME + Nº'!E62="SIM",0,IF((M280=X20), V280+IF(H259="SIM",IF((P280=X20),SUM(V281:V284), 0)), IF(H259="SIM",IF((P280=X20),SUM(V281:V284), 0)))) -> 0 | EF20: =IF(AE33=X20,AE49,0) -> 0 | EG20: =IF('NOME + Nº'!D28="SIM",SUM(AB20:EF20),0) -> 0 | EI20: =SUM(EB20:EE20) -> 0
H21: NOME | L21: =IF(K20="SIM","1","0") -> 0 | M21: =M16 -> 20 | R21: =O20/(Q20) -> 9.0322581 | W21: 8 | X21: Alça pronta | Y21: ='NOME + Nº'!C66 -> Alça ANNA B 30mm | Z21: =IF(Y21<>0,LOOKUP(Y21,ListaDeEstoque[DESCRIÇÃO],ListaDeEstoque[Preço unitário]),0) -> #N/A | AA21: =IF(Y21<>0,LOOKUP(Y21,ListaDeEstoque[DESCRIÇÃO],ListaDeEstoque[Largura e Dimensões]),0) -> #N/A | AB21: =IF((K259=Y21), V259, 0) -> 0.36397647 | AC21: - | AD21: - | AE21: - | AF21: =SUM(AB21:AE21) -> 0.36397647
B22: Todas as medidas devem estar em centímetros (cm). | J22: =J20+1 -> 6 | K22: NÃO | L22: 1 | M22: Entretela | N22: =IF((M22=X14),Z14,(IF((M22=X15),Z15,(IF((M22=X16),Z16,(IF((M22=X17),Z17,(IF((M22=X18),Z18,(IF((M22=X19),Z19,(IF((M22=X20),Z20))))))))))))) -> 16 | O22: =IF((M22=X14),AA14,(IF((M22=X15),AA15,(IF((M22=X16),AA16,(IF((M22=X17),AA17,(IF((M22=X18),AA18,(IF((M22=X19),AA19,(IF((M22=X20),AA20))))))))))))) -> 75 | P22: =P20 -> 21.4 | Q22: =Q20 -> 15.5 | R22: =IF(R23<(M23*L22), INT(R23),(M23*L22)) -> 4 | S22: =IF(K22="SIM",(N22*L22*(P22/100)/R22)*L23,0) -> 0 | T22: =R23*L23 -> 0 | W22: 9 | X22: Alça pronta | Y22: ='NOME + Nº'!C67 -> 0 | Z22: =IF(Y22<>0,LOOKUP(Y22,ListaDeEstoque[DESCRIÇÃO],ListaDeEstoque[Preço unitário]),0) -> 0 | AA22: =IF(Y22<>0,LOOKUP(Y22,ListaDeEstoque[DESCRIÇÃO],ListaDeEstoque[Largura e Dimensões]),0) -> 0 | AB22: - | AC22: =IF((K266=Y22), V266, 0) -> 0 | AD22: - | AE22: - | AF22: =SUM(AB22:AE22) -> 0 | EE22: CONSUMO TOTAL | EG22: =SUM(EG14:EG20) -> 8.9467765 | EI22: =SUM(EI14:EI20) -> 0.73108758
L23: =IF(K22="SIM","1","0") -> 0 | M23: =M21 -> 20 | R23: =O22/(Q22) -> 4.8387097 | W23: 10 | X23: Alça pronta | Y23: ='NOME + Nº'!C68 -> 0 | Z23: =IF(Y23<>0,LOOKUP(Y23,ListaDeEstoque[DESCRIÇÃO],ListaDeEstoque[Preço unitário]),0) -> 0 | AA23: =IF(Y23<>0,LOOKUP(Y23,ListaDeEstoque[DESCRIÇÃO],ListaDeEstoque[Largura e Dimensões]),0) -> 0 | AB23: - | AC23: - | AD23: =IF((K273=Y23), V273, 0) -> 0 | AE23: - | AF23: =SUM(AB23:AE23) -> 0
J24: =J22+1 -> 7 | K24: NÃO | L24: 1 | M24: Forro | N24: =IF((M24=X14),Z14,(IF((M24=X15),Z15,(IF((M24=X16),Z16,(IF((M24=X17),Z17,(IF((M24=X18),Z18,(IF((M24=X19),Z19,(IF((M24=X20),Z20))))))))))))) -> 19.9 | O24: =IF((M24=X14),AA14,(IF((M24=X15),AA15,(IF((M24=X16),AA16,(IF((M24=X17),AA17,(IF((M24=X18),AA18,(IF((M24=X19),AA19,(IF((M24=X20),AA20))))))))))))) -> 140 | P24: =P22 -> 21.4 | Q24: =Q22 -> 15.5 | R24: =IF(R25<(M25*L24), INT(R25),(M25*L24)) -> 9 | S24: =IF(K24="SIM",(N24*L24*(P24/100)/R24)*L25,0) -> 0 | T24: =R25*L25 -> 0 | W24: 11 | X24: Alça pronta | Y24: ='NOME + Nº'!C69 -> 0 | Z24: =IF(Y24<>0,LOOKUP(Y24,ListaDeEstoque[DESCRIÇÃO],ListaDeEstoque[Preço unitário]),0) -> 0 | AA24: =IF(Y24<>0,LOOKUP(Y24,ListaDeEstoque[DESCRIÇÃO],ListaDeEstoque[Largura e Dimensões]),0) -> 0 | AB24: - | AC24: - | AD24: - | AE24: =IF((K280=Y24), V280, 0) -> 0 | AF24: =SUM(AB24:AE24) -> 0
L25: =IF(K24="SIM","1","0") -> 0 | M25: =M23 -> 20 | R25: =O24/(Q24) -> 9.0322581 | W25: 12 | X25: Alça pronta | Y25: ='NOME + Nº'!C70 -> 0 | Z25: =IF(Y25<>0,LOOKUP(Y25,ListaDeEstoque[DESCRIÇÃO],ListaDeEstoque[Preço unitário]),0) -> 0 | AA25: =IF(Y25<>0,LOOKUP(Y25,ListaDeEstoque[DESCRIÇÃO],ListaDeEstoque[Largura e Dimensões]),0) -> 0 | AB25: =IF((K259=Y25), V259, 0) -> 0 | AC25: =IF((K266=Y25), V266, 0) -> 0 | AD25: =IF((K273=Y25), V273, 0) -> 0 | AE25: =IF((K280=Y25), V280, 0) -> 0 | AF25: =SUM(AB25:AE25) -> 0
